Inside custom test 'invoke' syscall
Inside exception handler, as expected
Stack backtrace passed sanity checks
